#异常处理
>&emsp;&emsp;异常处理(exception handling)机制允许程序中独立开发的部分能够在运行时就出现的问题进行通信并做出相应的处理。异常使得我们能够将问题的检测与解决过程分离开来。

* C++内置了异常处理的语法元素try...catch...
  * try语句处理正常代码逻辑
  * catch语句处理异常情况
  * try语句中的异常由对应的catch语句处理
* C++通过throw语句抛出异常信息
* throw抛出的异常必须被catch处理
  * 当前函数能够处理异常，程序继续往下执行
  * 当前函数无法处理异常，则函数停止执行，并返回
* 当执行一个throw时，throw后面的语句将不再被执行
* 程序的控制权从throw转移到与之匹配的catch模块
  * 沿着调用链的函数可能会提早退出
  * 一旦程序开始执行异常处理代码，则沿着调用链创建的对象将被销毁

#栈展开
未被处理的异常会顺着函数调用栈向上传播，直到被处理为止，否则程序将调用terminate函数终止程序的执行。

#C++ 异常处理
* catch语句可以定义具体处理的异常类型
* 不同类型的异常由不同的catch语句负责处理
* try语句中可以抛出任何类型的异常
* catch(...)用于处理所有类型的异常
* 任何异常都只能被捕获一次

#异常处理的匹配规则
* 异常抛出后，自上而下严格匹配每一个catch语句参数类型
* 异常处理匹配时，不进行任何的类型转换
  * 允许非常量向常量的的类型转换
  * 允许从派生类向基类的类型转换，所以派生类放在catch块上方
  * 数组被转换成指向数组类型的指针
  * 函数被转换成指向该函数类型的指针
  
示例代码

    #include <iostream>
    #include <string>
    using namespace std;
    
    void Demo1(){
      try {
        throw 'c';
      } catch(char c) {
        cout << "catch(char c)" << endl;
      } catch(short c) {
        cout << "catch(short c)" << endl;
      } catch(double c) { 
        cout << "catch(double c)" << endl;
      } catch(...) {
        cout << "catch(...)" << endl;
      }
    }
    
    void Demo2(){
      throw string("Exception test");
    }
    
    int main(){
      Demo1();
      try{
        Demo2();
      } catch(char* s) {
        cout << "catch(char* s)" << endl;
      } catch(const char* cs) {
        cout << "catch(const char* cs)" << endl;
      } catch(string ss){
        cout << "catch(string ss)" << endl;
      }
    
      return 0;
    }


#重新抛出
* catch中捕获的异常可以被重新解释后抛出
* 工程开发中使用这样的方式统一异常类型

示例代码：

    #include <iostream>
    #include <string>
    using namespace std;
    
    void Demo1(){
      try {
        throw 'c';
      } catch(char c) {
        cout << "catch(char c)" << endl;
      } catch(short c) {
        cout << "catch(short c)" << endl;
      } catch(double c) { 
        cout << "catch(double c)" << endl;
      } catch(...) {
        cout << "catch(...)" << endl;
      }
    }
    
    void Demo2(){
      throw string("Exception test");
    }
    
    int main(){
      Demo1();
      try{
        Demo2();
      } catch(char* s) {
        cout << "catch(char* s)" << endl;
      } catch(const char* cs) {
        cout << "catch(const char* cs)" << endl;
      } catch(string ss){
        cout << "catch(string ss)" << endl;
      }
    
      return 0;
    }